<?xml version="1.0"?>
<sdf version="1.8">
  <world name="imu_world">

    <!-- ========== SYSTEM PLUGINS ========== -->
    <plugin filename="gz-sim-physics-system"
            name="gz::sim::systems::Physics"/>
    <plugin filename="gz-sim-imu-system"
            name="gz::sim::systems::Imu"/>
    <plugin filename="gz-sim-scene-broadcaster-system"
            name="gz::sim::systems::SceneBroadcaster"/>
    <plugin filename="gz-sim-user-commands-system"
            name="gz::sim::systems::UserCommands"/>

    <!-- ========== PHYSICS ========== -->
    <physics name="default_physics" type="ode">
      <max_step_size>0.001</max_step_size>
      <real_time_factor>1.0</real_time_factor>
      <real_time_update_rate>1000</real_time_update_rate>
    </physics>

    <!-- ========== LIGHTING ========== -->
    <light name="sun" type="directional">
      <cast_shadows>true</cast_shadows>
      <pose>0 0 10 0 0 0</pose>
      <diffuse>0.9 0.9 0.9 1</diffuse>
      <specular>0.3 0.3 0.3 1</specular>
      <direction>-0.5 0.1 -0.9</direction>
    </light>

    <!-- ========== GROUND PLANE ========== -->
    <model name="ground_plane">
      <static>true</static>
      <link name="link">
        <collision name="collision">
          <geometry>
            <plane>
              <normal>0 0 1</normal>
              <size>20 20</size>
            </plane>
          </geometry>
          <surface>
            <friction>
              <ode>
                <mu>1.0</mu>
                <mu2>1.0</mu2>
              </ode>
            </friction>
          </surface>
        </collision>
        <visual name="visual">
          <geometry>
            <plane>
              <normal>0 0 1</normal>
              <size>20 20</size>
            </plane>
          </geometry>
          <material>
            <ambient>0.3 0.3 0.3 1</ambient>
            <diffuse>0.6 0.6 0.6 1</diffuse>
          </material>
        </visual>
      </link>
    </model>

    <!-- ========== BUMP ========== -->
    <model name="bump">
      <static>true</static>
      <pose>1.0 0 0.025 0 0 0</pose>
      <link name="link">
        <collision name="collision">
          <geometry>
            <cylinder>
              <radius>0.3</radius>
              <length>0.05</length>
            </cylinder>
          </geometry>
        </collision>
        <visual name="visual">
          <geometry>
            <cylinder>
              <radius>0.3</radius>
              <length>0.05</length>
            </cylinder>
          </geometry>
          <material>
            <ambient>0.2 0.7 0.2 1</ambient>
            <diffuse>0.3 0.8 0.3 1</diffuse>
          </material>
        </visual>
      </link>
    </model>

    <!-- ========== RAMP ========== -->
    <model name="ramp">
      <static>true</static>
      <pose>2.5 0 0.15 0 -0.2 0</pose>
      <link name="link">
        <collision name="collision">
          <geometry>
            <box>
              <size>2.0 1.5 0.05</size>
            </box>
          </geometry>
        </collision>
        <visual name="visual">
          <geometry>
            <box>
              <size>2.0 1.5 0.05</size>
            </box>
          </geometry>
          <material>
            <ambient>0.6 0.4 0.2 1</ambient>
            <diffuse>0.7 0.5 0.3 1</diffuse>
          </material>
        </visual>
      </link>
    </model>

    <!-- ========== WALL 1 ========== -->
    <model name="wall_1">
      <static>true</static>
      <pose>0 3 0.25 0 0 0</pose>
      <link name="link">
        <collision name="collision">
          <geometry>
            <box><size>4.0 0.1 0.5</size></box>
          </geometry>
        </collision>
        <visual name="visual">
          <geometry>
            <box><size>4.0 0.1 0.5</size></box>
          </geometry>
          <material>
            <ambient>0.8 0.2 0.2 1</ambient>
            <diffuse>0.9 0.3 0.3 1</diffuse>
          </material>
        </visual>
      </link>
    </model>

    <!-- ========== WALL 2 ========== -->
    <model name="wall_2">
      <static>true</static>
      <pose>0 -3 0.25 0 0 0</pose>
      <link name="link">
        <collision name="collision">
          <geometry>
            <box><size>4.0 0.1 0.5</size></box>
          </geometry>
        </collision>
        <visual name="visual">
          <geometry>
            <box><size>4.0 0.1 0.5</size></box>
          </geometry>
          <material>
            <ambient>0.8 0.2 0.2 1</ambient>
            <diffuse>0.9 0.3 0.3 1</diffuse>
          </material>
        </visual>
      </link>
    </model>

    <!-- ========== MOBILE ROBOT ========== -->
    <model name="mobile_robot">
      <pose>0 0 0.1 0 0 0</pose>

      <link name="base_link">
        <inertial>
          <mass>5.1</mass>
          <inertia>
            <ixx>0.101</ixx><ixy>0</ixy><ixz>0</ixz>
            <iyy>0.101</iyy><iyz>0</iyz>
            <izz>0.101</izz>
          </inertia>
        </inertial>
        <collision name="base_link_collision">
          <geometry>
            <box><size>0.4 0.3 0.1</size></box>
          </geometry>
        </collision>
        <visual name="base_link_visual">
          <geometry>
            <box><size>0.4 0.3 0.1</size></box>
          </geometry>
          <material>
            <ambient>0 0 1 1</ambient>
            <diffuse>0 0 1 1</diffuse>
          </material>
        </visual>

        <sensor name="imu_sensor" type="imu">
          <pose>0 0 0.05 0 0 0</pose>
          <always_on>true</always_on>
          <update_rate>__IMU_RATE_HZ__</update_rate>
          <topic>/imu/data</topic>
          <imu>
            <angular_velocity>
              <x><noise type="gaussian"><mean>0.0</mean><stddev>0.0002</stddev></noise></x>
              <y><noise type="gaussian"><mean>0.0</mean><stddev>0.0002</stddev></noise></y>
              <z><noise type="gaussian"><mean>0.0</mean><stddev>0.0002</stddev></noise></z>
            </angular_velocity>
            <linear_acceleration>
              <x><noise type="gaussian"><mean>0.0</mean><stddev>0.017</stddev></noise></x>
              <y><noise type="gaussian"><mean>0.0</mean><stddev>0.017</stddev></noise></y>
              <z><noise type="gaussian"><mean>0.0</mean><stddev>0.017</stddev></noise></z>
            </linear_acceleration>
          </imu>
        </sensor>

      </link>

      <joint name="left_wheel_joint" type="revolute">
        <parent>base_link</parent>
        <child>left_wheel</child>
        <pose relative_to="base_link">0 0.15 -0.05 0 1.57 0</pose>
        <axis>
          <xyz>0 0 1</xyz>
          <limit><lower>-1e+16</lower><upper>1e+16</upper></limit>
        </axis>
      </joint>

      <link name="left_wheel">
        <pose relative_to="left_wheel_joint">0 0 0 0 0 0</pose>
        <inertial>
          <mass>1.0</mass>
          <inertia>
            <ixx>0.01</ixx><ixy>0</ixy><ixz>0</ixz>
            <iyy>0.01</iyy><iyz>0</iyz><izz>0.01</izz>
          </inertia>
        </inertial>
        <collision name="left_wheel_collision">
          <geometry>
            <cylinder><radius>0.05</radius><length>0.02</length></cylinder>
          </geometry>
        </collision>
        <visual name="left_wheel_visual">
          <geometry>
            <cylinder><radius>0.05</radius><length>0.02</length></cylinder>
          </geometry>
          <material>
            <ambient>0 0 0 1</ambient>
            <diffuse>0 0 0 1</diffuse>
          </material>
        </visual>
      </link>

      <joint name="right_wheel_joint" type="revolute">
        <parent>base_link</parent>
        <child>right_wheel</child>
        <pose relative_to="base_link">0 -0.15 -0.05 0 1.57 0</pose>
        <axis>
          <xyz>0 0 1</xyz>
          <limit><lower>-1e+16</lower><upper>1e+16</upper></limit>
        </axis>
      </joint>

      <link name="right_wheel">
        <pose relative_to="right_wheel_joint">0 0 0 0 0 0</pose>
        <inertial>
          <mass>1.0</mass>
          <inertia>
            <ixx>0.01</ixx><ixy>0</ixy><ixz>0</ixz>
            <iyy>0.01</iyy><iyz>0</iyz><izz>0.01</izz>
          </inertia>
        </inertial>
        <collision name="right_wheel_collision">
          <geometry>
            <cylinder><radius>0.05</radius><length>0.02</length></cylinder>
          </geometry>
        </collision>
        <visual name="right_wheel_visual">
          <geometry>
            <cylinder><radius>0.05</radius><length>0.02</length></cylinder>
          </geometry>
          <material>
            <ambient>0 0 0 1</ambient>
            <diffuse>0 0 0 1</diffuse>
          </material>
        </visual>
      </link>

      <plugin filename="gz-sim-diff-drive-system"
              name="gz::sim::systems::DiffDrive">
        <left_joint>left_wheel_joint</left_joint>
        <right_joint>right_wheel_joint</right_joint>
        <wheel_separation>0.30</wheel_separation>
        <wheel_radius>0.05</wheel_radius>
        <topic>/cmd_vel</topic>
        <odom_topic>/odom</odom_topic>
        <frame_id>odom</frame_id>
        <child_frame_id>base_link</child_frame_id>
        <max_linear_acceleration>2.0</max_linear_acceleration>
        <max_angular_acceleration>4.0</max_angular_acceleration>
      </plugin>

    </model>

  </world>
</sdf>
