<?xml version="1.0"?>
<robot name="mobile_robot">

  <link name="base_link">
    <visual>
      <geometry>
        <box size="0.4 0.3 0.1"/>
      </geometry>
    </visual>
    <collision>
      <geometry>
        <box size="0.4 0.3 0.1"/>
      </geometry>
      <surface>
        <friction>
          <ode>
            <mu>5.0</mu>
            <mu2>5.0</mu2>
          </ode>
        </friction>
      </surface>
    </collision>
    <inertial>
      <mass value="2.0"/>
      <origin xyz="0 0 0"/>
      <inertia ixx="0.05" ixy="0" ixz="0"
               iyy="0.05" iyz="0"
               izz="0.05"/>
    </inertial>
  </link>

  <link name="left_wheel">
    <visual>
      <geometry>
        <cylinder radius="0.05" length="0.02"/>
      </geometry>
    </visual>
    <collision>
      <geometry>
        <cylinder radius="0.05" length="0.02"/>
      </geometry>
      <surface>
        <friction>
          <ode>
            <mu>10.0</mu>
            <mu2>10.0</mu2>
          </ode>
        </friction>
        <contact>
          <ode>
            <kp>100000.0</kp>
            <kd>1.0</kd>
          </ode>
        </contact>
      </surface>
    </collision>
    <inertial>
      <mass value="0.5"/>
      <inertia ixx="0.005" ixy="0" ixz="0"
               iyy="0.005" iyz="0"
               izz="0.005"/>
    </inertial>
  </link>

  <joint name="left_wheel_joint" type="continuous">
    <parent link="base_link"/>
    <child link="left_wheel"/>
    <origin xyz="0 0.15 -0.03" rpy="0 1.57 0"/>
    <axis xyz="0 0 1"/>
    <dynamics damping="1.0" friction="0.5"/>
  </joint>

  <link name="right_wheel">
    <visual>
      <geometry>
        <cylinder radius="0.05" length="0.02"/>
      </geometry>
    </visual>
    <collision>
      <geometry>
        <cylinder radius="0.05" length="0.02"/>
      </geometry>
      <surface>
        <friction>
          <ode>
            <mu>10.0</mu>
            <mu2>10.0</mu2>
          </ode>
        </friction>
        <contact>
          <ode>
            <kp>100000.0</kp>
            <kd>1.0</kd>
          </ode>
        </contact>
      </surface>
    </collision>
    <inertial>
      <mass value="0.5"/>
      <inertia ixx="0.005" ixy="0" ixz="0"
               iyy="0.005" iyz="0"
               izz="0.005"/>
    </inertial>
  </link>

  <joint name="right_wheel_joint" type="continuous">
    <parent link="base_link"/>
    <child link="right_wheel"/>
    <origin xyz="0 -0.15 -0.03" rpy="0 1.57 0"/>
    <axis xyz="0 0 1"/>
    <dynamics damping="1.0" friction="0.5"/>
  </joint>

  <link name="imu_link">
    <inertial>
      <mass value="0.1"/>
      <inertia ixx="0.001" ixy="0" ixz="0"
               iyy="0.001" iyz="0"
               izz="0.001"/>
    </inertial>
  </link>

  <joint name="imu_joint" type="fixed">
    <parent link="base_link"/>
    <child link="imu_link"/>
    <origin xyz="0 0 0.05"/>
  </joint>

  <gazebo reference="imu_link">
    <sensor name="imu_sensor" type="imu">
      <always_on>true</always_on>
      <update_rate>100.0</update_rate>
    </sensor>
  </gazebo>

  <gazebo>
    <plugin name="diff_drive" filename="libignition-gazebo-diff-drive-system.so">
      <left_joint>left_wheel_joint</left_joint>
      <right_joint>right_wheel_joint</right_joint>
      <wheel_separation>0.3</wheel_separation>
      <wheel_radius>0.05</wheel_radius>
      <topic>cmd_vel</topic>
    </plugin>
  </gazebo>

</robot>
